Traceback (most recent call last):
  File "/opt/homebrew/Caskroom/miniconda/base/envs/turtle/lib/python3.10/site-packages/jupyter_cache/executors/utils.py", line 51, in single_nb_execution
    executenb(
  File "/opt/homebrew/Caskroom/miniconda/base/envs/turtle/lib/python3.10/site-packages/nbclient/client.py", line 1204, in execute
    return NotebookClient(nb=nb, resources=resources, km=km, **kwargs).execute()
  File "/opt/homebrew/Caskroom/miniconda/base/envs/turtle/lib/python3.10/site-packages/nbclient/util.py", line 84, in wrapped
    return just_run(coro(*args, **kwargs))
  File "/opt/homebrew/Caskroom/miniconda/base/envs/turtle/lib/python3.10/site-packages/nbclient/util.py", line 62, in just_run
    return loop.run_until_complete(coro)
  File "/opt/homebrew/Caskroom/miniconda/base/envs/turtle/lib/python3.10/asyncio/base_events.py", line 649, in run_until_complete
    return future.result()
  File "/opt/homebrew/Caskroom/miniconda/base/envs/turtle/lib/python3.10/site-packages/nbclient/client.py", line 663, in async_execute
    await self.async_execute_cell(
  File "/opt/homebrew/Caskroom/miniconda/base/envs/turtle/lib/python3.10/site-packages/nbclient/client.py", line 965, in async_execute_cell
    await self._check_raise_for_error(cell, cell_index, exec_reply)
  File "/opt/homebrew/Caskroom/miniconda/base/envs/turtle/lib/python3.10/site-packages/nbclient/client.py", line 862, in _check_raise_for_error
    raise CellExecutionError.from_cell_and_msg(cell, exec_reply_content)
nbclient.exceptions.CellExecutionError: An error occurred while executing the following cell:
------------------
import matplotlib.pylab as plt

# Datenimport Messdaten
x = [-20, -15, -10, -5, 0, 5]
y = [152.38, 124.43, 88.91, 37.43, 5.52, -27.41]
    
# Parabel durch die Messdaten
y_parabel = []
for zahl in x:
    y_parabel.append(zahl**2)
   
# Plot der Messdaten mit zusÃ¤tzlicher Parabel
plt.figure()
plt.scatter(x,y)
plt.plot(x, y_parabel)
plt.xlabel('Temperatur')
plt.ylabel('Materialeigenschaft')
plt.titel('Messdaten');
------------------

[0;31m---------------------------------------------------------------------------[0m
[0;31mAttributeError[0m                            Traceback (most recent call last)
Cell [0;32mIn[18], line 18[0m
[1;32m     16[0m plt[38;5;241m.[39mxlabel([38;5;124m'[39m[38;5;124mTemperatur[39m[38;5;124m'[39m)
[1;32m     17[0m plt[38;5;241m.[39mylabel([38;5;124m'[39m[38;5;124mMaterialeigenschaft[39m[38;5;124m'[39m)
[0;32m---> 18[0m [43mplt[49m[38;5;241;43m.[39;49m[43mtitel[49m([38;5;124m'[39m[38;5;124mMessdaten[39m[38;5;124m'[39m);

[0;31mAttributeError[0m: module 'matplotlib.pylab' has no attribute 'titel'
AttributeError: module 'matplotlib.pylab' has no attribute 'titel'

